Workbook
Name _Key2: #REF!
Name _Sort: #REF!
Name BALANCE___SHEET: #REF!
Name CASH_AND_SHORT_TERM_FUNDS: #REF!
Name _Key1: #REF!
Name FDFRF: #REF!

Sheet CA SUMMARY
D8: 0 | L8: 3
D9: CAPITAL ALLOWANCE COMPUTATION FOR 2022 YEAR OF ASSESSMENT
D10: SN | E10: CATEGORY | F10: TWDV BF | G10: ADDITION | H10: TWDV ON DISP | I10: INITIAL | J10: ANNUAL | K10: TOTAL | L10: TWDV CF
D11: 1 | E11: LEASEHOLD IMPROVEMENT | F11: ='CA LEASHOLD IMPROVEMENT'!F11 -> 4.0264899e+08 | G11: ='CA LEASHOLD IMPROVEMENT'!G11 -> 79066607 | H11: ='CA LEASHOLD IMPROVEMENT'!H11 -> 0 | I11: ='CA LEASHOLD IMPROVEMENT'!I11 -> 11859991 | J11: ='CA LEASHOLD IMPROVEMENT'!J11 -> 52206178 | K11: ='CA LEASHOLD IMPROVEMENT'!K11 -> 64066169 | L11: ='CA LEASHOLD IMPROVEMENT'!L11 -> 4.1764943e+08
D12: 2 | E12: MOTOR VEHICLE | F12: ='CA MOTOR VEHICLE'!F12 -> 4582125 | G12: ='CA MOTOR VEHICLE'!G12 -> 8.7395427e+08 | H12: ='CA MOTOR VEHICLE'!H12 -> 0 | I12: ='CA MOTOR VEHICLE'!I12 -> 4.3697713e+08 | J12: ='CA MOTOR VEHICLE'!J12 -> 1.4718642e+08 | K12: ='CA MOTOR VEHICLE'!K12 -> 5.8416355e+08 | L12: ='CA MOTOR VEHICLE'!L12 -> 2.9437284e+08
D13: 3 | E13: FURNITURE AND FITTINGS | F13: ='CA FURNITURE AND FITTING'!F13 -> 75349601 | G13: ='CA FURNITURE AND FITTING'!G13 -> 1.4867755e+08 | H13: ='CA FURNITURE AND FITTING'!H13 -> 0 | I13: ='CA FURNITURE AND FITTING'!I13 -> 37169387 | J13: ='CA FURNITURE AND FITTING'!J13 -> 46714441 | K13: ='CA FURNITURE AND FITTING'!K13 -> 83883828 | L13: ='CA FURNITURE AND FITTING'!L13 -> 1.4014332e+08
D14: 4 | E14: COMPUTER EQUIPMENT | F14: ='CA COMPUTER EQUIPMENTS'!G17 -> 3.3553296e+08 | G14: ='CA COMPUTER EQUIPMENTS'!H17 -> 2.0724647e+08 | H14: ='CA COMPUTER EQUIPMENTS'!I17 -> 0 | I14: ='CA COMPUTER EQUIPMENTS'!J17 -> 1.0362324e+08 | J14: ='CA COMPUTER EQUIPMENTS'!K17 -> 1.463854e+08 | K14: ='CA COMPUTER EQUIPMENTS'!L17 -> 2.5000864e+08 | L14: ='CA COMPUTER EQUIPMENTS'!M17 -> 2.927708e+08
D15: 5 | E15: OFFICE EQUIPMENT | F15: ='CA OFFICE EQUIPMENTS'!G17 -> 0 | G15: ='CA OFFICE EQUIPMENTS'!H17 -> 75520572 | H15: ='CA OFFICE EQUIPMENTS'!I17 -> 0 | I15: ='CA OFFICE EQUIPMENTS'!J17 -> 37760286 | J15: ='CA OFFICE EQUIPMENTS'!K17 -> 9440071.5 | K15: ='CA OFFICE EQUIPMENTS'!L17 -> 47200358 | L15: ='CA OFFICE EQUIPMENTS'!M17 -> 28320215
D16: 6 | E16: COMPUTER SOFTWARE | F16: ='COMPUTER SOFTWARE'!F15 -> 2.5349563e+08 | G16: ='COMPUTER SOFTWARE'!G15 -> 4.3239436e+08 | H16: ='COMPUTER SOFTWARE'!H15 -> 0 | I16: ='COMPUTER SOFTWARE'!I15 -> 2.1619718e+08 | J16: ='COMPUTER SOFTWARE'!J15 -> 1.5656427e+08 | K16: ='COMPUTER SOFTWARE'!K15 -> 3.7276145e+08 | L16: ='COMPUTER SOFTWARE'!L15 -> 3.1312854e+08
F17: =SUM(F11:F16) -> 1.0716093e+09 | G17: =SUM(G11:G16) -> 1.8168598e+09 | H17: =SUM(H11:H16) -> 0 | I17: =SUM(I11:I16) -> 8.4358721e+08 | J17: =SUM(J11:J16) -> 5.5849678e+08 | K17: =SUM(K11:K16) -> 1.402084e+09 | L17: =SUM(L11:L16) -> 1.4863851e+09

Sheet CA LEASHOLD IMPROVEMENT
B4: 1
C7: 0 | I7: 0.15 | J7: 0.1 | M7: 3
C8: CA- LEASEHOLD IMROVEMENT
B9: SN | C9: DETAILS | D9: YEAR OF ACQUISITION | E9: UNEXP LF BF | F9: TWDV BF | G9: ADDITIONS | H9: TWDV ON DISP | I9: INITIAL ALLOWANCE | J9: ANNUAL ALLOWANCE | K9: TOTAL CA | L9: TWDV CF | M9: UXPRD LF CF
B10: 3 | C10: 0 | D10: 2022 | E10: 10 | F10: 0 | G10: 526338549 | H10: 0 | I10: =15%*G10 -> 78950782 | J10: =(G10-I10)/E10 -> 44738777 | K10: =I10+J10 -> 1.2368956e+08 | L10: =G10-K10 -> 4.0264899e+08 | M10: 9
B11: 2 | C11: 0 | D11: 2023 | E11: 9 | F11: =L10 -> 4.0264899e+08 | G11: 79066607 | H11: 0 | I11: =15%*G11 -> 11859991 | J11: =(G11-I11)/E11+(J10) -> 52206178 | K11: =I11+J11 -> 64066169 | L11: =(F11+G11)-K11 -> 4.1764943e+08 | M11: 8
F13: =SUM(F10:F12) -> 4.0264899e+08 | G13: =SUM(G10:G12) -> 6.0540516e+08 | H13: =SUM(H10:H12) -> 0 | I13: =SUM(I10:I12) -> 90810773 | J13: =SUM(J10:J12) -> 96944955 | K13: =SUM(K10:K12) -> 1.8775573e+08 | L13: =SUM(L10:L12) -> 8.2029842e+08

Sheet CA MOTOR VEHICLE
C8: 0 | I8: 0.5 | J8: 0.25 | M8: 3
C9: CA- MOTOR VEHICLE
B10: SN | C10: DETAILS | D10: YEAR OF ACQUISITION | E10: UNEXP LF BF | F10: TWDV BF | G10: ADDITIONS | H10: TWDV ON DISP | I10: INITIAL ALLOWANCE | J10: ANNUAL ALLOWANCE | K10: TOTAL CA | L10: TWDV CF | M10: UXPRD LF CF
B11: 1 | C11: 0 | D11: 2022 | E11: 4 | F11: 0 | G11: 12219000 | H11: 0 | I11: =G11*50% -> 6109500 | J11: =(G11-I11)/4 -> 1527375 | K11: =I11+J11 -> 7636875 | L11: =G11-K11 -> 4582125 | M11: 3 | XFD11: =SUM(B11:XFC11) -> 32076905
B12: 2 | D12: 2023 | E12: 3 | F12: =L11 -> 4582125 | G12: 8.7395427e+08 | I12: =50%*G12 -> 4.3697713e+08 | J12: =(G12-I12)/E12+(J11) -> 1.4718642e+08 | K12: =I12+J12 -> 5.8416355e+08 | L12: =(F12+G12)-K12 -> 2.9437284e+08 | M12: 2 | XFD12: =SUM(B12:XFC12) -> 2.3412384e+09
F13: =SUM(F11:F12) -> 4582125 | G13: =SUM(G11:G12) -> 8.8617327e+08 | H13: =SUM(H11:H12) -> 0 | I13: =SUM(I11:I12) -> 4.4308663e+08 | J13: =SUM(J11:J12) -> 1.4871379e+08 | K13: =SUM(K11:K12) -> 5.9180043e+08 | L13: =SUM(L11:L12) -> 2.9895496e+08

Sheet CA FURNITURE AND FITTING
C8: 0 | I8: 0.25 | J8: 0.2 | M8: 3
C9: CA- FURNITURES AND FITTINGS
B10: SN | C10: DETAILS | D10: YEAR OF ACQUISITION | E10: UNEXP LF BF | F10: TWDV BF | G10: ADDITIONS | H10: TWDV ON DISP | I10: INITIAL ALLOWANCE | J10: ANNUAL ALLOWANCE | K10: TOTAL CA | L10: TWDV CF | M10: UXPRD LF CF
B11: 1 | C11: 0 | D11: 0 | E11: 0 | G11: 0 | H11: 0 | J11: 0 | K11: 0 | L11: 0 | M11: 0
B12: 2 | C12: 0 | D12: 2022 | E12: 5 | G12: 125582668 | H12: 0 | I12: =G12*25% -> 31395667 | J12: =(G12-I12)/E12 -> 18837400 | K12: =I12+J12 -> 50233067 | L12: =G12-K12 -> 75349601 | M12: 4
B13: 3 | C13: 0 | D13: 2023 | E13: 4 | F13: =L12 -> 75349601 | G13: 1.4867755e+08 | H13: 0 | I13: =25%*G13 -> 37169387 | J13: =(G13-I13)/E13+(J12) -> 46714441 | K13: =I13+J13 -> 83883828 | L13: =(F13+G13)-K13 -> 1.4014332e+08 | M13: 3
F16: =SUM(F11:F15) -> 75349601 | G16: =SUM(G11:G15) -> 2.7426022e+08 | H16: =SUM(H11:H15) -> 0 | I16: =SUM(I11:I15) -> 68565054 | J16: =SUM(J11:J15) -> 65551841 | K16: =SUM(K11:K15) -> 1.3411689e+08 | L16: =SUM(L11:L15) -> 2.1549292e+08

Sheet CA COMPUTER EQUIPMENTS
D10: 0 | J10: 0.5 | K10: 0.25 | N10: 3
D11: CA- COMPUTER EQUIPMENTS
C12: SN | D12: DETAILS | E12: YEAR OF ACQUISITION | F12: UNEXP LF BF | G12: TWDV BF | H12: ADDITIONS | I12: TWDV ON DISP | J12: INITIAL ALLOWANCE | K12: ANNUAL ALLOWANCE | L12: TOTAL CA | M12: TWDV CF | N12: UXPRD LF CF
C13: 1 | D13: 0 | E13: 0 | F13: 0 | G13: 0 | H13: 0 | I13: 0 | J13: 0 | K13: 0 | L13: 0 | M13: 0 | N13: 0
C14: 2 | D14: 0 | E14: 0 | F14: 0 | G14: 0 | H14: 0 | I14: 0 | J14: 0 | K14: 0 | L14: 0 | M14: 0 | N14: 0
C15: 3 | D15: 0 | E15: 0 | F15: 0 | G15: 0 | H15: 0 | I15: 0 | J15: 0 | K15: 0 | L15: 0 | M15: 0 | N15: 0
C16: 4 | D16: 0 | E16: 2022 | F16: 4 | G16: 0 | H16: 894754569 | I16: 0 | J16: =H16*50% -> 4.4737728e+08 | K16: =(H16-J16)/F16 -> 1.1184432e+08 | L16: =J16+K16 -> 5.5922161e+08 | M16: =H16-L16 -> 3.3553296e+08 | N16: 3
C17: 5 | D17: 0 | E17: 2023 | F17: 3 | G17: =M16 -> 3.3553296e+08 | H17: 2.0724647e+08 | I17: 0 | J17: =50%*H17 -> 1.0362324e+08 | K17: =(H17-J17)/F17+(K16) -> 1.463854e+08 | L17: =J17+K17 -> 2.5000864e+08 | M17: =(G17+H17)-L17 -> 2.927708e+08
G18: 0
G19: 0
G20: 0
G21: 0
G22: =SUM(G13:G21) -> 3.3553296e+08 | H22: =SUM(H13:H21) -> 1.102001e+09 | I22: =SUM(I13:I21) -> 0 | J22: =SUM(J13:J21) -> 5.5100052e+08 | K22: =SUM(K13:K21) -> 2.5822972e+08 | L22: =SUM(L13:L21) -> 8.0923024e+08 | M22: =SUM(M13:M21) -> 6.2830376e+08

Sheet CA OFFICE EQUIPMENTS
D11: 0 | J11: 0.5 | K11: 0.25 | N11: 3
D12: CA- OFFICE EQUIPMENTS
C13: SN | D13: DETAILS | E13: YEAR OF ACQUISITION | F13: UNEXP LF BF | G13: TWDV BF | H13: ADDITIONS | I13: TWDV ON DISP | J13: INITIAL ALLOWANCE | K13: ANNUAL ALLOWANCE | L13: TOTAL CA | M13: TWDV CF | N13: UXPRD LF CF
C14: 1 | D14: 0 | E14: 0 | F14: 0 | G14: 0 | I14: 0 | K14: 0 | L14: 0 | M14: 0 | N14: 0
C15: 1 | D15: 0 | E15: 0 | F15: 0 | G15: 0 | I15: 0 | K15: 0 | L15: 0 | M15: 0 | N15: 0
C16: 1 | D16: 0 | E16: 0 | F16: 0 | G16: 0 | I16: 0 | K16: 0 | L16: 0 | M16: 0 | N16: 0
C17: 1 | D17: 0 | E17: 2023 | F17: 4 | G17: 0 | H17: 75520572 | I17: 0 | J17: =50%*H17 -> 37760286 | K17: =(H17-J17)/F17 -> 9440071.5 | L17: =J17+K17 -> 47200358 | M17: =H17-L17 -> 28320215 | N17: 0
G18: =SUM(G14:G17) -> 0 | H18: =SUM(H14:H17) -> 75520572 | I18: =SUM(I14:I17) -> 0 | J18: =SUM(J14:J17) -> 37760286 | K18: =SUM(K14:K17) -> 9440071.5 | L18: =SUM(L14:L17) -> 47200358 | M18: =SUM(M14:M17) -> 28320215

Sheet COMPUTER SOFTWARE
C8: 0 | I8: 0.5 | J8: 0.25 | M8: 3
C9: CA- COMPUTER SOTWARE
B10: SN | C10: DETAILS | D10: YEAR OF ACQUISITION | E10: UNEXP LF BF | F10: TWDV BF | G10: ADDITIONS | H10: TWDV ON DISP | I10: INITIAL ALLOWANCE | J10: ANNUAL ALLOWANCE | K10: TOTAL CA | L10: TWDV CF | M10: UXPRD LF CF
B11: 1 | C11: 0 | D11: 0 | E11: 0 | F11: 0 | H11: 0 | I11: 0 | J11: 0 | K11: 0 | L11: 0 | M11: 0
B12: 2 | C12: 0 | D12: 0 | E12: 0 | F12: 0 | H12: 0 | J12: 0 | K12: 0 | L12: 0 | M12: 0
B13: 3 | C13: 0 | D13: 0 | E13: 0 | F13: 0 | H13: 0 | J13: 0 | K13: 0 | L13: 0 | M13: 0
B14: 4 | C14: 0 | D14: 2022 | E14: 4 | F14: 0 | G14: 675988355 | H14: 0 | I14: =G14*I8 -> 3.3799418e+08 | J14: =(G14-I14)/4 -> 84498544 | K14: =I14+J14 -> 4.2249272e+08 | L14: =G14-K14 -> 2.5349563e+08 | M14: 3
B15: 5 | C15: 0 | D15: 2023 | E15: 3 | F15: =L14 -> 2.5349563e+08 | G15: 4.3239436e+08 | H15: 0 | I15: =50%*G15 -> 2.1619718e+08 | J15: =(G15-I15)/E15+(J14) -> 1.5656427e+08 | K15: =I15+J15 -> 3.7276145e+08 | L15: =(F15+G15)-K15 -> 3.1312854e+08 | M15: 2
F17: =SUM(F11:F14) -> 0 | G17: =SUM(G11:G14) -> 675988355 | H17: =SUM(H11:H14) -> 0 | I17: =SUM(I11:I14) -> 3.3799418e+08 | J17: =SUM(J11:J14) -> 84498544 | K17: =SUM(K11:K14) -> 4.2249272e+08 | L17: =SUM(L11:L14) -> 2.5349563e+08

Sheet INCOME TAX COMP
C6: 0 | E6: 1
C7: INCOME TAX COMPUTATION FOR 2023 YEAR OF ASSESSMENT
D8: NGN | E8: NGN
C9: Profit before Tax | E9: 574675000
C11: Add back:
C12: ='[2]INPUT 2'!B9 -> Public Relations, Promotions & Adverts | D12: 2.4952341e+08
C13: ='[2]INPUT 2'!B10 -> Impairment charge | D13: ='[2]INPUT 2'!C10 -> 0
C14: ='[2]INPUT 2'!B15 -> Depreciation for Right of use | D14: ='[2]INPUT 2'!C15 -> 15156000
C15: ='[2]INPUT 2'!B16 -> Entertainment | D15: ='[2]INPUT 2'!C16 -> 18957389
C16: ='[2]INPUT 2'!B17 -> Loss on disposal of asset | D16: ='[2]INPUT 2'!C17 -> 0
C17: 0 | D17: 0
C18: 0 | D18: 0
C19: 0 | D19: 0
C20: 0 | D20: 0
C21: 0 | D21: 0
C22: 0 | D22: 0
C23: 0 | D23: 0
C24: 0 | D24: 0
C25: 0 | D25: 0
C26: 0 | D26: 0
C27: 0 | D27: 0
C28: 0 | D28: 0
... C46: 0 | D46: 0
C47: Total Disallowable Expenses | E47: =SUM(D12:D46) -> 2.836368e+08
C48: Sub-Total | E48: =SUM(E9:E47) -> 8.583118e+08
C49: 0
C50: ='[2]INPUT 2'!B54 -> Impairment write back | D50: ='[2]INPUT 2'!C54 -> 0
C51: 0 | D51: 0
C52: 0 | D52: 0
C53: 0 | D53: 0
C54: 0 | D54: 0
C55: 0 | D55: 0
C56: 0 | D56: 0
C57: 0 | D57: 0
C58: 0 | D58: 0
C59: 0 | D59: 0
C60: 0 | D60: 0
C61: 0 | D61: 0
C62: 0 | D62: 0
... C85: 0 | D85: 0
...

Sheet INPUT 2
B3: INCOME STATEMENT AND STATEMENT OF FINANCIAL POSITION INFORMATION
B4: REPORTING CURRENCY | C4: NGN
B5: Profit/Loss before Tax | C5: 574675000
B7: ADD BACK DISALLOWED EXPENSES:
B8: Category A: Permanent add backs
B9: Depreciation | C9: 4.8591171e+08
B10: Public Relations, Promotions & Adverts | C10: 2.4952341e+08 | D10: 2.4952341e+08
B11: Impairment charge | C11: 0
B12: Donations
B13: Bad and uncollectible debts
B14: Legal fee relating capital expenditure & Penalty | C14: 0
B15: Lease expense
B16: Depreciation for Right of use | C16: 96964337
B17: Entertainment
B18: Loss on disposal of asset
B32: Expense on Exempt/Non-Taxable Incomes | C32: =IF(C103>0,C103,'[1]DISALLOWABLE COST OF EXEMPT INC'!C16) -> #REF!
B33: =IF('[1]INPUT 1'!B17="YES",'[1]RELATED PARTY LOAN'!C18,0) -> #REF! | C33: =IF('[1]INPUT 1'!B17="YES",'[2]INPUT 2'!B132,0) -> #REF!
B35: Category B: Timing Differences | C35: 0
B36: Provision for Bad debt | C36: 0
B37: Gratuity & Redundancy Benefits
B42: Category C: Other taxable Income Omitted
B51: LESS NON TAXABLE INCOME
B52: Category A: Exempt Income
B53: Dividend income
B54: Interest income on FGN Bond | C54: 1246573.3
B55: Impairment write back
B56: Foreign exchange Revaluation gain
B57: Prior year unrealise loss now realised
B69: Category B: Capital Gains
B70: Gain on disposal of property and equipment
B74: Category C: Unrealised gains
B80: Category D: Other Non Taxable Income
B90: INCOME/MINIMUN TAX INFORMATION:
B91: TURNOVER/SALES/REVENUE | C91: 1242316000
B93: OTHER INCOMES | C93: 467000
B95: FINANCE INCOME | C95: 1252038000
B97: FRANKED INVESTMENT INCOME | C97: 0
B99: TOTAL COST AS PER AFS (DIRECT COST & OPEX) | C99: 1641668000
B101: AVAILABLE COSTS OF EXEMPT INCOMES | C101: NO
B103: IDENTIFIED COST OF EXEMPT INCOME
...
